Workbook

Sheet PIVOT
A3: Row Labels | B3: Sum of Revenue_clean | F3: Row Labels | G3: Sum of Revenue_clean | K3: Average of delivery_days_clean
A4: Asia | B4: 89357.5 | F4: Unknown | G4: 147975.07 | K4: 3.2220039
A5: Unknown | B5: 195727.39 | F5: Mobile | G5: 214306.98
A6: USA | B6: 205070.84 | F6: Online | G6: 348509.29
A7: Europe | B7: 220635.61 | F7: Grand Total | G7: 710791.34
A8: Grand Total | B8: 710791.34
A12: Row Labels | B12: Count of order_id_clean | F12: Row Labels | G12: Count of order_id_clean
A13: Laptop | B13: 158 | F13: Pending | G13: 103 | I13: =GETPIVOTDATA("order_id_clean",$F$12,"order_stauts_clean","Delivered") -> 218
A14: Phone | B14: 191 | F14: Unknown | G14: 109
A15: Tablet | B15: 193 | F15: Returned | G15: 190 | I15: =(GETPIVOTDATA("order_id_clean",$F$12,"order_stauts_clean","Returned")) -> 190
A16: Unknown | B16: 78 | F16: Delivered | G16: 218
A17: Grand Total | B17: 620 | F17: Grand Total | G17: 620 | I17: =I15/(I15+I13) -> 0.46568627

Sheet Raw_ecommerce
A1: order_id | B1: order_id_clean | C1: order_date | D1: order_date_clean | E1: customer_name | F1: Customer_name_clean | G1: region | H1: Region_clean | I1: sales_channel | J1: Sales_channel_clean | K1: product | L1: Product_clean | M1: quantity | N1: Quantity_clean | O1: revenue | P1: Revenue_clean | Q1: currency | R1: currency_clean | S1: order_status | T1: order_stauts_clean | U1: delivery_days | V1: delivery_days_clean | W1: notes
A2: 1000 | B2: =IF(ISBLANK(Table1[[#This Row],[order_id]]),"",IF(LEFT(Table1[[#This Row],[order_id]],3)="ORD",Table1[[#This Row],[order_id]],"ORD-" & Table1[[#This Row],[order_id]])) -> ORD-1000 | C2: 23/11/2024 | D2: =IFERROR(DATEVALUE(Table1[[#This Row],[order_date]]),"") -> 45619 | E2: customer 0 | F2: =IF(ISBLANK(Table1[[#This Row],[customer_name]]),"Unknown Customer",PROPER(SUBSTITUTE(Table1[[#This Row],[customer_name]],"Cust.","Customer"))) -> Customer 0 | H2: =IFERROR(_xlfn.XLOOKUP(Table1[[#This Row],[region]],Mappings!$C$3:$C$8,Mappings!$D$3:$D$8,,0,1),"Unknown") -> Unknown | I2: Online | J2: =IFERROR(_xlfn.XLOOKUP(Table1[[#This Row],[sales_channel]],Table4[Original],Table4[Clean],,0,1),"Unknown") -> Online | K2: TABLET | L2: =IFERROR(_xlfn.XLOOKUP(Table1[[#This Row],[product]],Table3[Original],Table3[Product_clean],,0,1),"Unknown") -> Tablet | N2: =IF(ISNUMBER(Table1[[#This Row],[quantity]]),Table1[[#This Row],[quantity]],IFERROR(VLOOKUP(Table1[[#This Row],[quantity]],Table5[#All],2,FALSE),"Unknown")) -> Unknown | O2: $378.43 | P2: =IFERROR(VALUE(SUBSTITUTE(SUBSTITUTE(SUBSTITUTE(Table1[[#This Row],[revenue]],"EUR",""),"$",""),".",",")),"") -> 378.43 | Q2: EUR | R2: =IF(OR(Table1[[#This Row],[currency]]="EUR",Table1[[#This Row],[currency]]="€"),"EUR",IF(OR(Table1[[#This Row],[currency]]="USD",Table1[[#This Row],[currency]]="$"),"USD","Unknown")) -> EUR | S2: pending | T2: =IFERROR(_xlfn.XLOOKUP(Table1[[#This Row],[order_status]],Table8[Original],Table8[Clean],,0,1),"Unknown") -> Pending | U2: 5 | V2: =IF(ISNUMBER(Table1[[#This Row],[delivery_days]]),Table1[[#This Row],[delivery_days]],IFERROR(_xlfn.XLOOKUP(Table1[[#This Row],[delivery_days]],Table57[Original],Table57[Clean],,0,1),"Unknown")) -> 5
B3: =IF(ISBLANK(Table1[[#This Row],[order_id]]),"",IF(LEFT(Table1[[#This Row],[order_id]],3)="ORD",Table1[[#This Row],[order_id]],"ORD-" & Table1[[#This Row],[order_id]])) | C3: 2024-01-16 | D3: =IFERROR(DATEVALUE(Table1[[#This Row],[order_date]]),"") -> 45307 | E3: customer 1 | F3: =IF(ISBLANK(Table1[[#This Row],[customer_name]]),"Unknown Customer",PROPER(SUBSTITUTE(Table1[[#This Row],[customer_name]],"Cust.","Customer"))) -> Customer 1 | H3: =IFERROR(_xlfn.XLOOKUP(Table1[[#This Row],[region]],Mappings!$C$3:$C$8,Mappings!$D$3:$D$8,,0,1),"Unknown") -> Unknown | J3: =IFERROR(_xlfn.XLOOKUP(Table1[[#This Row],[sales_channel]],Table4[Original],Table4[Clean],,0,1),"Unknown") -> Unknown | K3: TABLET | L3: =IFERROR(_xlfn.XLOOKUP(Table1[[#This Row],[product]],Table3[Original],Table3[Product_clean],,0,1),"Unknown") -> Tablet | N3: =IF(ISNUMBER(Table1[[#This Row],[quantity]]),Table1[[#This Row],[quantity]],IFERROR(VLOOKUP(Table1[[#This Row],[quantity]],Table5[#All],2,FALSE),"Unknown")) -> Unknown | O3: 326.4 EUR | P3: =IFERROR(VALUE(SUBSTITUTE(SUBSTITUTE(SUBSTITUTE(Table1[[#This Row],[revenue]],"EUR",""),"$",""),".",",")),"") -> 326.4 | Q3: $ | R3: =IF(OR(Table1[[#This Row],[currency]]="EUR",Table1[[#This Row],[currency]]="€"),"EUR",IF(OR(Table1[[#This Row],[currency]]="USD",Table1[[#This Row],[currency]]="$"),"USD","Unknown")) -> USD | S3: Delivered | T3: =IFERROR(_xlfn.XLOOKUP(Table1[[#This Row],[order_status]],Table8[Original],Table8[Clean],,0,1),"Unknown") -> Delivered | U3: 5 | V3: =IF(ISNUMBER(Table1[[#This Row],[delivery_days]]),Table1[[#This Row],[delivery_days]],IFERROR(_xlfn.XLOOKUP(Table1[[#This Row],[delivery_days]],Table57[Original],Table57[Clean],,0,1),"Unknown")) -> 5 | W3: VIP
B4: =IF(ISBLANK(Table1[[#This Row],[order_id]]),"",IF(LEFT(Table1[[#This Row],[order_id]],3)="ORD",Table1[[#This Row],[order_id]],"ORD-" & Table1[[#This Row],[order_id]])) | D4: =IFERROR(DATEVALUE(Table1[[#This Row],[order_date]]),"") | E4: Cust. 2 | F4: =IF(ISBLANK(Table1[[#This Row],[customer_name]]),"Unknown Customer",PROPER(SUBSTITUTE(Table1[[#This Row],[customer_name]],"Cust.","Customer"))) -> Customer 2 | G4: Asia | H4: =IFERROR(_xlfn.XLOOKUP(Table1[[#This Row],[region]],Mappings!$C$3:$C$8,Mappings!$D$3:$D$8,,0,1),"Unknown") -> Asia | I4: online | J4: =IFERROR(_xlfn.XLOOKUP(Table1[[#This Row],[sales_channel]],Table4[Original],Table4[Clean],,0,1),"Unknown") -> Online | K4: Lapotp | L4: =IFERROR(_xlfn.XLOOKUP(Table1[[#This Row],[product]],Table3[Original],Table3[Product_clean],,0,1),"Unknown") -> Laptop | M4: 3 | N4: =IF(ISNUMBER(Table1[[#This Row],[quantity]]),Table1[[#This Row],[quantity]],IFERROR(VLOOKUP(Table1[[#This Row],[quantity]],Table5[#All],2,FALSE),"Unknown")) -> 3 | O4: 2614.44 EUR | P4: =IFERROR(VALUE(SUBSTITUTE(SUBSTITUTE(SUBSTITUTE(Table1[[#This Row],[revenue]],"EUR",""),"$",""),".",",")),"") -> 2614.44 | Q4: EUR | R4: =IF(OR(Table1[[#This Row],[currency]]="EUR",Table1[[#This Row],[currency]]="€"),"EUR",IF(OR(Table1[[#This Row],[currency]]="USD",Table1[[#This Row],[currency]]="$"),"USD","Unknown")) -> EUR | S4: delivered | T4: =IFERROR(_xlfn.XLOOKUP(Table1[[#This Row],[order_status]],Table8[Original],Table8[Clean],,0,1),"Unknown") -> Delivered | U4: 5 | V4: =IF(ISNUMBER(Table1[[#This Row],[delivery_days]]),Table1[[#This Row],[delivery_days]],IFERROR(_xlfn.XLOOKUP(Table1[[#This Row],[delivery_days]],Table57[Original],Table57[Clean],,0,1),"Unknown")) -> 5
A5: 1003 | B5: =IF(ISBLANK(Table1[[#This Row],[order_id]]),"",IF(LEFT(Table1[[#This Row],[order_id]],3)="ORD",Table1[[#This Row],[order_id]],"ORD-" & Table1[[#This Row],[order_id]])) -> ORD-1003 | D5: =IFERROR(DATEVALUE(Table1[[#This Row],[order_date]]),"") | E5: Customer 3 | F5: =IF(ISBLANK(Table1[[#This Row],[customer_name]]),"Unknown Customer",PROPER(SUBSTITUTE(Table1[[#This Row],[customer_name]],"Cust.","Customer"))) -> Customer 3 | G5: europe | H5: =IFERROR(_xlfn.XLOOKUP(Table1[[#This Row],[region]],Mappings!$C$3:$C$8,Mappings!$D$3:$D$8,,0,1),"Unknown") -> Europe | I5: Online | J5: =IFERROR(_xlfn.XLOOKUP(Table1[[#This Row],[sales_channel]],Table4[Original],Table4[Clean],,0,1),"Unknown") -> Online | K5: Tablet | L5: =IFERROR(_xlfn.XLOOKUP(Table1[[#This Row],[product]],Table3[Original],Table3[Product_clean],,0,1),"Unknown") -> Tablet | M5: 3 | N5: =IF(ISNUMBER(Table1[[#This Row],[quantity]]),Table1[[#This Row],[quantity]],IFERROR(VLOOKUP(Table1[[#This Row],[quantity]],Table5[#All],2,FALSE),"Unknown")) -> 3 | O5: $2550.11 | P5: =IFERROR(VALUE(SUBSTITUTE(SUBSTITUTE(SUBSTITUTE(Table1[[#This Row],[revenue]],"EUR",""),"$",""),".",",")),"") -> 2550.11 | R5: =IF(OR(Table1[[#This Row],[currency]]="EUR",Table1[[#This Row],[currency]]="€"),"EUR",IF(OR(Table1[[#This Row],[currency]]="USD",Table1[[#This Row],[currency]]="$"),"USD","Unknown")) -> Unknown | S5: RETURNED | T5: =IFERROR(_xlfn.XLOOKUP(Table1[[#This Row],[order_status]],Table8[Original],Table8[Clean],,0,1),"Unknown") -> Returned | U5: five | V5: =IF(ISNUMBER(Table1[[#This Row],[delivery_days]]),Table1[[#This Row],[delivery_days]],IFERROR(_xlfn.XLOOKUP(Table1[[#This Row],[delivery_days]],Table57[Original],Table57[Clean],,0,1),"Unknown")) -> 5 | W5: late delivery
A6: ORD-1004 | B6: =IF(ISBLANK(Table1[[#This Row],[order_id]]),"",IF(LEFT(Table1[[#This Row],[order_id]],3)="ORD",Table1[[#This Row],[order_id]],"ORD-" & Table1[[#This Row],[order_id]])) -> ORD-1004 | C6: 2024-12-26 | D6: =IFERROR(DATEVALUE(Table1[[#This Row],[order_date]]),"") -> 45652 | E6: customer 4 | F6: =IF(ISBLANK(Table1[[#This Row],[customer_name]]),"Unknown Customer",PROPER(SUBSTITUTE(Table1[[#This Row],[customer_name]],"Cust.","Customer"))) -> Customer 4 | H6: =IFERROR(_xlfn.XLOOKUP(Table1[[#This Row],[region]],Mappings!$C$3:$C$8,Mappings!$D$3:$D$8,,0,1),"Unknown") -> Unknown | I6: Online | J6: =IFERROR(_xlfn.XLOOKUP(Table1[[#This Row],[sales_channel]],Table4[Original],Table4[Clean],,0,1),"Unknown") -> Online | K6: phone | L6: =IFERROR(_xlfn.XLOOKUP(Table1[[#This Row],[product]],Table3[Original],Table3[Product_clean],,0,1),"Unknown") -> Phone | M6: 3 | N6: =IF(ISNUMBER(Table1[[#This Row],[quantity]]),Table1[[#This Row],[quantity]],IFERROR(VLOOKUP(Table1[[#This Row],[quantity]],Table5[#All],2,FALSE),"Unknown")) -> 3 | O6: 255.19 EUR | P6: =IFERROR(VALUE(SUBSTITUTE(SUBSTITUTE(SUBSTITUTE(Table1[[#This Row],[revenue]],"EUR",""),"$",""),".",",")),"") -> 255.19 | Q6: $ | R6: =IF(OR(Table1[[#This Row],[currency]]="EUR",Table1[[#This Row],[currency]]="€"),"EUR",IF(OR(Table1[[#This Row],[currency]]="USD",Table1[[#This Row],[currency]]="$"),"USD","Unknown")) -> USD | T6: =IFERROR(_xlfn.XLOOKUP(Table1[[#This Row],[order_status]],Table8[Original],Table8[Clean],,0,1),"Unknown") -> Unknown | U6: 3 | V6: =IF(ISNUMBER(Table1[[#This Row],[delivery_days]]),Table1[[#This Row],[delivery_days]],IFERROR(_xlfn.XLOOKUP(Table1[[#This Row],[delivery_days]],Table57[Original],Table57[Clean],,0,1),"Unknown")) -> 3 | W6: late delivery
B7: =IF(ISBLANK(Table1[[#This Row],[order_id]]),"",IF(LEFT(Table1[[#This Row],[order_id]],3)="ORD",Table1[[#This Row],[order_id]],"ORD-" & Table1[[#This Row],[order_id]])) | C7: 2024-07-08 | D7: =IFERROR(DATEVALUE(Table1[[#This Row],[order_date]]),"") -> 45481 | E7: customer 5 | F7: =IF(ISBLANK(Table1[[#This Row],[customer_name]]),"Unknown Customer",PROPER(SUBSTITUTE(Table1[[#This Row],[customer_name]],"Cust.","Customer"))) -> Customer 5 | G7: U.S. | H7: =IFERROR(_xlfn.XLOOKUP(Table1[[#This Row],[region]],Mappings!$C$3:$C$8,Mappings!$D$3:$D$8,,0,1),"Unknown") -> USA | J7: =IFERROR(_xlfn.XLOOKUP(Table1[[#This Row],[sales_channel]],Table4[Original],Table4[Clean],,0,1),"Unknown") -> Unknown | K7: Lapotp | L7: =IFERROR(_xlfn.XLOOKUP(Table1[[#This Row],[product]],Table3[Original],Table3[Product_clean],,0,1),"Unknown") -> Laptop | M7: 2 | N7: =IF(ISNUMBER(Table1[[#This Row],[quantity]]),Table1[[#This Row],[quantity]],IFERROR(VLOOKUP(Table1[[#This Row],[quantity]],Table5[#All],2,FALSE),"Unknown")) -> 2 | O7: $1098.05 | P7: =IFERROR(VALUE(SUBSTITUTE(SUBSTITUTE(SUBSTITUTE(Table1[[#This Row],[revenue]],"EUR",""),"$",""),".",",")),"") -> 1098.05 | Q7: $ | R7: =IF(OR(Table1[[#This Row],[currency]]="EUR",Table1[[#This Row],[currency]]="€"),"EUR",IF(OR(Table1[[#This Row],[currency]]="USD",Table1[[#This Row],[currency]]="$"),"USD","Unknown")) -> USD | S7: returned | T7: =IFERROR(_xlfn.XLOOKUP(Table1[[#This Row],[order_status]],Table8[Original],Table8[Clean],,0,1),"Unknown") -> Returned | U7: 3 | V7: =IF(ISNUMBER(Table1[[#This Row],[delivery_days]]),Table1[[#This Row],[delivery_days]],IFERROR(_xlfn.XLOOKUP(Table1[[#This Row],[delivery_days]],Table57[Original],Table57[Clean],,0,1),"Unknown")) -> 3 | W7: late delivery
A8: 1006 | B8: =IF(ISBLANK(Table1[[#This Row],[order_id]]),"",IF(LEFT(Table1[[#This Row],[order_id]],3)="ORD",Table1[[#This Row],[order_id]],"ORD-" & Table1[[#This Row],[order_id]])) -> ORD-1006 | C8: 2024-12-16 | D8: =IFERROR(DATEVALUE(Table1[[#This Row],[order_date]]),"") -> 45642 | E8: Cust. 6 | F8: =IF(ISBLANK(Table1[[#This Row],[customer_name]]),"Unknown Customer",PROPER(SUBSTITUTE(Table1[[#This Row],[customer_name]],"Cust.","Customer"))) -> Customer 6 | G8: europe | H8: =IFERROR(_xlfn.XLOOKUP(Table1[[#This Row],[region]],Mappings!$C$3:$C$8,Mappings!$D$3:$D$8,,0,1),"Unknown") -> Europe | I8: Mobile | J8: =IFERROR(_xlfn.XLOOKUP(Table1[[#This Row],[sales_channel]],Table4[Original],Table4[Clean],,0,1),"Unknown") -> Mobile | K8: Laptop | L8: =IFERROR(_xlfn.XLOOKUP(Table1[[#This Row],[product]],Table3[Original],Table3[Product_clean],,0,1),"Unknown") -> Laptop | M8: 2 | N8: =IF(ISNUMBER(Table1[[#This Row],[quantity]]),Table1[[#This Row],[quantity]],IFERROR(VLOOKUP(Table1[[#This Row],[quantity]],Table5[#All],2,FALSE),"Unknown")) -> 2 | O8: 1006.63 | P8: =IFERROR(VALUE(SUBSTITUTE(SUBSTITUTE(SUBSTITUTE(Table1[[#This Row],[revenue]],"EUR",""),"$",""),".",",")),"") -> 1006.63 | R8: =IF(OR(Table1[[#This Row],[currency]]="EUR",Table1[[#This Row],[currency]]="€"),"EUR",IF(OR(Table1[[#This Row],[currency]]="USD",Table1[[#This Row],[currency]]="$"),"USD","Unknown")) -> Unknown | T8: =IFERROR(_xlfn.XLOOKUP(Table1[[#This Row],[order_status]],Table8[Original],Table8[Clean],,0,1),"Unknown") -> Unknown | U8: 3 | V8: =IF(ISNUMBER(Table1[[#This Row],[delivery_days]]),Table1[[#This Row],[delivery_days]],IFERROR(_xlfn.XLOOKUP(Table1[[#This Row],[delivery_days]],Table57[Original],Table57[Clean],,0,1),"Unknown")) -> 3 | W8: late delivery
A9: 1007 | B9: =IF(ISBLANK(Table1[[#This Row],[order_id]]),"",IF(LEFT(Table1[[#This Row],[order_id]],3)="ORD",Table1[[#This Row],[order_id]],"ORD-" & Table1[[#This Row],[order_id]])) -> ORD-1007 | C9: 12-01-2024 | D9: =IFERROR(DATEVALUE(Table1[[#This Row],[order_date]]),"") -> 45303 | E9: customer 7 | F9: =IF(ISBLANK(Table1[[#This Row],[customer_name]]),"Unknown Customer",PROPER(SUBSTITUTE(Table1[[#This Row],[customer_name]],"Cust.","Customer"))) -> Customer 7 | G9: US | H9: =IFERROR(_xlfn.XLOOKUP(Table1[[#This Row],[region]],Mappings!$C$3:$C$8,Mappings!$D$3:$D$8,,0,1),"Unknown") -> USA | J9: =IFERROR(_xlfn.XLOOKUP(Table1[[#This Row],[sales_channel]],Table4[Original],Table4[Clean],,0,1),"Unknown") -> Unknown | K9: Tablet | L9: =IFERROR(_xlfn.XLOOKUP(Table1[[#This Row],[product]],Table3[Original],Table3[Product_clean],,0,1),"Unknown") -> Tablet | N9: =IF(ISNUMBER(Table1[[#This Row],[quantity]]),Table1[[#This Row],[quantity]],IFERROR(VLOOKUP(Table1[[#This Row],[quantity]],Table5[#All],2,FALSE),"Unknown")) -> Unknown | P9: =IFERROR(VALUE(SUBSTITUTE(SUBSTITUTE(SUBSTITUTE(Table1[[#This Row],[revenue]],"EUR",""),"$",""),".",",")),"") | Q9: € | R9: =IF(OR(Table1[[#This Row],[currency]]="EUR",Table1[[#This Row],[currency]]="€"),"EUR",IF(OR(Table1[[#This Row],[currency]]="USD",Table1[[#This Row],[currency]]="$"),"USD","Unknown")) -> EUR | T9: =IFERROR(_xlfn.XLOOKUP(Table1[[#This Row],[order_status]],Table8[Original],Table8[Clean],,0,1),"Unknown") -> Unknown | U9: five | V9: =IF(ISNUMBER(Table1[[#This Row],[delivery_days]]),Table1[[#This Row],[delivery_days]],IFERROR(_xlfn.XLOOKUP(Table1[[#This Row],[delivery_days]],Table57[Original],Table57[Clean],,0,1),"Unknown")) -> 5
A10: 1008 | B10: =IF(ISBLANK(Table1[[#This Row],[order_id]]),"",IF(LEFT(Table1[[#This Row],[order_id]],3)="ORD",Table1[[#This Row],[order_id]],"ORD-" & Table1[[#This Row],[order_id]])) -> ORD-1008 | D10: =IFERROR(DATEVALUE(Table1[[#This Row],[order_date]]),"") | E10: Customer 8 | F10: =IF(ISBLANK(Table1[[#This Row],[customer_name]]),"Unknown Customer",PROPER(SUBSTITUTE(Table1[[#This Row],[customer_name]],"Cust.","Customer"))) -> Customer 8 | H10: =IFERROR(_xlfn.XLOOKUP(Table1[[#This Row],[region]],Mappings!$C$3:$C$8,Mappings!$D$3:$D$8,,0,1),"Unknown") -> Unknown | I10: Online | J10: =IFERROR(_xlfn.XLOOKUP(Table1[[#This Row],[sales_channel]],Table4[Original],Table4[Clean],,0,1),"Unknown") -> Online | L10: =IFERROR(_xlfn.XLOOKUP(Table1[[#This Row],[product]],Table3[Original],Table3[Product_clean],,0,1),"Unknown") -> Unknown | M10: 1 | N10: =IF(ISNUMBER(Table1[[#This Row],[quantity]]),Table1[[#This Row],[quantity]],IFERROR(VLOOKUP(Table1[[#This Row],[quantity]],Table5[#All],2,FALSE),"Unknown")) -> 1 | O10: 1228.23 EUR | P10: =IFERROR(VALUE(SUBSTITUTE(SUBSTITUTE(SUBSTITUTE(Table1[[#This Row],[revenue]],"EUR",""),"$",""),".",",")),"") -> 1228.23 | Q10: USD | R10: =IF(OR(Table1[[#This Row],[currency]]="EUR",Table1[[#This Row],[currency]]="€"),"EUR",IF(OR(Table1[[#This Row],[currency]]="USD",Table1[[#This Row],[currency]]="$"),"USD","Unknown")) -> USD | T10: =IFERROR(_xlfn.XLOOKUP(Table1[[#This Row],[order_status]],Table8[Original],Table8[Clean],,0,1),"Unknown") -> Unknown | U10: 2 | V10: =IF(ISNUMBER(Table1[[#This Row],[delivery_days]]),Table1[[#This Row],[delivery_days]],IFERROR(_xlfn.XLOOKUP(Table1[[#This Row],[delivery_days]],Table57[Original],Table57[Clean],,0,1),"Unknown")) -> 2
B11: =IF(ISBLANK(Table1[[#This Row],[order_id]]),"",IF(LEFT(Table1[[#This Row],[order_id]],3)="ORD",Table1[[#This Row],[order_id]],"ORD-" & Table1[[#This Row],[order_id]])) | D11: =IFERROR(DATEVALUE(Table1[[#This Row],[order_date]]),"") | E11: Cust. 9 | F11: =IF(ISBLANK(Table1[[#This Row],[customer_name]]),"Unknown Customer",PROPER(SUBSTITUTE(Table1[[#This Row],[customer_name]],"Cust.","Customer"))) -> Customer 9 | G11: U.S. | H11: =IFERROR(_xlfn.XLOOKUP(Table1[[#This Row],[region]],Mappings!$C$3:$C$8,Mappings!$D$3:$D$8,,0,1),"Unknown") -> USA | I11: Online | J11: =IFERROR(_xlfn.XLOOKUP(Table1[[#This Row],[sales_channel]],Table4[Original],Table4[Clean],,0,1),"Unknown") -> Online | K11: TABLET | L11: =IFERROR(_xlfn.XLOOKUP(Table1[[#This Row],[product]],Table3[Original],Table3[Product_clean],,0,1),"Unknown") -> Tablet | M11: 1 | N11: =IF(ISNUMBER(Table1[[#This Row],[quantity]]),Table1[[#This Row],[quantity]],IFERROR(VLOOKUP(Table1[[#This Row],[quantity]],Table5[#All],2,FALSE),"Unknown")) -> 1 | P11: =IFERROR(VALUE(SUBSTITUTE(SUBSTITUTE(SUBSTITUTE(Table1[[#This Row],[revenue]],"EUR",""),"$",""),".",",")),"") | R11: =IF(OR(Table1[[#This Row],[currency]]="EUR",Table1[[#This Row],[currency]]="€"),"EUR",IF(OR(Table1[[#This Row],[currency]]="USD",Table1[[#This Row],[currency]]="$"),"USD","Unknown")) -> Unknown | S11: RETURNED | T11: =IFERROR(_xlfn.XLOOKUP(Table1[[#This Row],[order_status]],Table8[Original],Table8[Clean],,0,1),"Unknown") -> Returned | V11: =IF(ISNUMBER(Table1[[#This Row],[delivery_days]]),Table1[[#This Row],[delivery_days]],IFERROR(_xlfn.XLOOKUP(Table1[[#This Row],[delivery_days]],Table57[Original],Table57[Clean],,0,1),"Unknown")) -> Unknown | W11: VIP
A12: ORD-1010 | B12: =IF(ISBLANK(Table1[[#This Row],[order_id]]),"",IF(LEFT(Table1[[#This Row],[order_id]],3)="ORD",Table1[[#This Row],[order_id]],"ORD-" & Table1[[#This Row],[order_id]])) -> ORD-1010 | C12: 2024-02-27 | D12: =IFERROR(DATEVALUE(Table1[[#This Row],[order_date]]),"") -> 45349 | E12: Cust. 10 | F12: =IF(ISBLANK(Table1[[#This Row],[customer_name]]),"Unknown Customer",PROPER(SUBSTITUTE(Table1[[#This Row],[customer_name]],"Cust.","Customer"))) -> Customer 10 | G12: U.S. | H12: =IFERROR(_xlfn.XLOOKUP(Table1[[#This Row],[region]],Mappings!$C$3:$C$8,Mappings!$D$3:$D$8,,0,1),"Unknown") -> USA | I12: online | J12: =IFERROR(_xlfn.XLOOKUP(Table1[[#This Row],[sales_channel]],Table4[Original],Table4[Clean],,0,1),"Unknown") -> Online | K12: Tablet | L12: =IFERROR(_xlfn.XLOOKUP(Table1[[#This Row],[product]],Table3[Original],Table3[Product_clean],,0,1),"Unknown") -> Tablet | M12: 1 | N12: =IF(ISNUMBER(Table1[[#This Row],[quantity]]),Table1[[#This Row],[quantity]],IFERROR(VLOOKUP(Table1[[#This Row],[quantity]],Table5[#All],2,FALSE),"Unknown")) -> 1 | O12: 915.83 EUR | P12: =IFERROR(VALUE(SUBSTITUTE(SUBSTITUTE(SUBSTITUTE(Table1[[#This Row],[revenue]],"EUR",""),"$",""),".",",")),"") -> 915.83 | Q12: € | R12: =IF(OR(Table1[[#This Row],[currency]]="EUR",Table1[[#This Row],[currency]]="€"),"EUR",IF(OR(Table1[[#This Row],[currency]]="USD",Table1[[#This Row],[currency]]="$"),"USD","Unknown")) -> EUR | T12: =IFERROR(_xlfn.XLOOKUP(Table1[[#This Row],[order_status]],Table8[Original],Table8[Clean],,0,1),"Unknown") -> Unknown | U12: five | V12: =IF(ISNUMBER(Table1[[#This Row],[delivery_days]]),Table1[[#This Row],[delivery_days]],IFERROR(_xlfn.XLOOKUP(Table1[[#This Row],[delivery_days]],Table57[Original],Table57[Clean],,0,1),"Unknown")) -> 5 | W12: late delivery
B13: =IF(ISBLANK(Table1[[#This Row],[order_id]]),"",IF(LEFT(Table1[[#This Row],[order_id]],3)="ORD",Table1[[#This Row],[order_id]],"ORD-" & Table1[[#This Row],[order_id]])) | C13: 2024-03-19 | D13: =IFERROR(DATEVALUE(Table1[[#This Row],[order_date]]),"") -> 45370 | E13: Cust. 11 | F13: =IF(ISBLANK(Table1[[#This Row],[customer_name]]),"Unknown Customer",PROPER(SUBSTITUTE(Table1[[#This Row],[customer_name]],"Cust.","Customer"))) -> Customer 11 | G13: europe | H13: =IFERROR(_xlfn.XLOOKUP(Table1[[#This Row],[region]],Mappings!$C$3:$C$8,Mappings!$D$3:$D$8,,0,1),"Unknown") -> Europe | I13: Online | J13: =IFERROR(_xlfn.XLOOKUP(Table1[[#This Row],[sales_channel]],Table4[Original],Table4[Clean],,0,1),"Unknown") -> Online | K13: Laptop | L13: =IFERROR(_xlfn.XLOOKUP(Table1[[#This Row],[product]],Table3[Original],Table3[Product_clean],,0,1),"Unknown") -> Laptop | M13: 3 | N13: =IF(ISNUMBER(Table1[[#This Row],[quantity]]),Table1[[#This Row],[quantity]],IFERROR(VLOOKUP(Table1[[#This Row],[quantity]],Table5[#All],2,FALSE),"Unknown")) -> 3 | O13: 1153.05 EUR | P13: =IFERROR(VALUE(SUBSTITUTE(SUBSTITUTE(SUBSTITUTE(Table1[[#This Row],[revenue]],"EUR",""),"$",""),".",",")),"") -> 1153.05 | Q13: € | R13: =IF(OR(Table1[[#This Row],[currency]]="EUR",Table1[[#This Row],[currency]]="€"),"EUR",IF(OR(Table1[[#This Row],[currency]]="USD",Table1[[#This Row],[currency]]="$"),"USD","Unknown")) -> EUR | S13: Delivered | T13: =IFERROR(_xlfn.XLOOKUP(Table1[[#This Row],[order_status]],Table8[Original],Table8[Clean],,0,1),"Unknown") -> Delivered | U13: 1 | V13: =IF(ISNUMBER(Table1[[#This Row],[delivery_days]]),Table1[[#This Row],[delivery_days]],IFERROR(_xlfn.XLOOKUP(Table1[[#This Row],[delivery_days]],Table57[Original],Table57[Clean],,0,1),"Unknown")) -> 1 | W13: late delivery
B14: =IF(ISBLANK(Table1[[#This Row],[order_id]]),"",IF(LEFT(Table1[[#This Row],[order_id]],3)="ORD",Table1[[#This Row],[order_id]],"ORD-" & Table1[[#This Row],[order_id]])) | D14: =IFERROR(DATEVALUE(Table1[[#This Row],[order_date]]),"") | E14: Customer 12 | F14: =IF(ISBLANK(Table1[[#This Row],[customer_name]]),"Unknown Customer",PROPER(SUBSTITUTE(Table1[[#This Row],[customer_name]],"Cust.","Customer"))) -> Customer 12 | H14: =IFERROR(_xlfn.XLOOKUP(Table1[[#This Row],[region]],Mappings!$C$3:$C$8,Mappings!$D$3:$D$8,,0,1),"Unknown") -> Unknown | I14: Web | J14: =IFERROR(_xlfn.XLOOKUP(Table1[[#This Row],[sales_channel]],Table4[Original],Table4[Clean],,0,1),"Unknown") -> Online | L14: =IFERROR(_xlfn.XLOOKUP(Table1[[#This Row],[product]],Table3[Original],Table3[Product_clean],,0,1),"Unknown") -> Unknown | M14: 2 | N14: =IF(ISNUMBER(Table1[[#This Row],[quantity]]),Table1[[#This Row],[quantity]],IFERROR(VLOOKUP(Table1[[#This Row],[quantity]],Table5[#All],2,FALSE),"Unknown")) -> 2 | O14: 2843.5 | P14: =IFERROR(VALUE(SUBSTITUTE(SUBSTITUTE(SUBSTITUTE(Table1[[#This Row],[revenue]],"EUR",""),"$",""),".",",")),"") -> 2843.5 | Q14: USD | R14: =IF(OR(Table1[[#This Row],[currency]]="EUR",Table1[[#This Row],[currency]]="€"),"EUR",IF(OR(Table1[[#This Row],[currency]]="USD",Table1[[#This Row],[currency]]="$"),"USD","Unknown")) -> USD | T14: =IFERROR(_xlfn.XLOOKUP(Table1[[#This Row],[order_status]],Table8[Original],Table8[Clean],,0,1),"Unknown") -> Unknown | U14: 5 | V14: =IF(ISNUMBER(Table1[[#This Row],[delivery_days]]),Table1[[#This Row],[delivery_days]],IFERROR(_xlfn.XLOOKUP(Table1[[#This Row],[delivery_days]],Table57[Original],Table57[Clean],,0,1),"Unknown")) -> 5 | W14: late delivery
A15: 1013 | B15: =IF(ISBLANK(Table1[[#This Row],[order_id]]),"",IF(LEFT(Table1[[#This Row],[order_id]],3)="ORD",Table1[[#This Row],[order_id]],"ORD-" & Table1[[#This Row],[order_id]])) -> ORD-1013 | C15: 15/05/2024 | D15: =IFERROR(DATEVALUE(Table1[[#This Row],[order_date]]),"") -> 45427 | E15: Cust. 13 | F15: =IF(ISBLANK(Table1[[#This Row],[customer_name]]),"Unknown Customer",PROPER(SUBSTITUTE(Table1[[#This Row],[customer_name]],"Cust.","Customer"))) -> Customer 13 | G15: europe | H15: =IFERROR(_xlfn.XLOOKUP(Table1[[#This Row],[region]],Mappings!$C$3:$C$8,Mappings!$D$3:$D$8,,0,1),"Unknown") -> Europe | J15: =IFERROR(_xlfn.XLOOKUP(Table1[[#This Row],[sales_channel]],Table4[Original],Table4[Clean],,0,1),"Unknown") -> Unknown | K15: TABLET | L15: =IFERROR(_xlfn.XLOOKUP(Table1[[#This Row],[product]],Table3[Original],Table3[Product_clean],,0,1),"Unknown") -> Tablet | M15: 3 | N15: =IF(ISNUMBER(Table1[[#This Row],[quantity]]),Table1[[#This Row],[quantity]],IFERROR(VLOOKUP(Table1[[#This Row],[quantity]],Table5[#All],2,FALSE),"Unknown")) -> 3 | P15: =IFERROR(VALUE(SUBSTITUTE(SUBSTITUTE(SUBSTITUTE(Table1[[#This Row],[revenue]],"EUR",""),"$",""),".",",")),"") | Q15: $ | R15: =IF(OR(Table1[[#This Row],[currency]]="EUR",Table1[[#This Row],[currency]]="€"),"EUR",IF(OR(Table1[[#This Row],[currency]]="USD",Table1[[#This Row],[currency]]="$"),"USD","Unknown")) -> USD | S15: pending | T15: =IFERROR(_xlfn.XLOOKUP(Table1[[#This Row],[order_status]],Table8[Original],Table8[Clean],,0,1),"Unknown") -> Pending | U15: 5 | V15: =IF(ISNUMBER(Table1[[#This Row],[delivery_days]]),Table1[[#This Row],[delivery_days]],IFERROR(_xlfn.XLOOKUP(Table1[[#This Row],[delivery_days]],Table57[Original],Table57[Clean],,0,1),"Unknown")) -> 5
A16: 1014 | B16: =IF(ISBLANK(Table1[[#This Row],[order_id]]),"",IF(LEFT(Table1[[#This Row],[order_id]],3)="ORD",Table1[[#This Row],[order_id]],"ORD-" & Table1[[#This Row],[order_id]])) -> ORD-1014 | C16: 06/05/2024 | D16: =IFERROR(DATEVALUE(Table1[[#This Row],[order_date]]),"") -> 45418 | E16: customer 14 | F16: =IF(ISBLANK(Table1[[#This Row],[customer_name]]),"Unknown Customer",PROPER(SUBSTITUTE(Table1[[#This Row],[customer_name]],"Cust.","Customer"))) -> Customer 14 | G16: EU | H16: =IFERROR(_xlfn.XLOOKUP(Table1[[#This Row],[region]],Mappings!$C$3:$C$8,Mappings!$D$3:$D$8,,0,1),"Unknown") -> Europe | I16: Online | J16: =IFERROR(_xlfn.XLOOKUP(Table1[[#This Row],[sales_channel]],Table4[Original],Table4[Clean],,0,1),"Unknown") -> Online | K16: TABLET | L16: =IFERROR(_xlfn.XLOOKUP(Table1[[#This Row],[product]],Table3[Original],Table3[Product_clean],,0,1),"Unknown") -> Tablet | M16: 1 | N16: =IF(ISNUMBER(Table1[[#This Row],[quantity]]),Table1[[#This Row],[quantity]],IFERROR(VLOOKUP(Table1[[#This Row],[quantity]],Table5[#All],2,FALSE),"Unknown")) -> 1 | O16: $712.86 | P16: =IFERROR(VALUE(SUBSTITUTE(SUBSTITUTE(SUBSTITUTE(Table1[[#This Row],[revenue]],"EUR",""),"$",""),".",",")),"") -> 712.86 | Q16: USD | R16: =IF(OR(Table1[[#This Row],[currency]]="EUR",Table1[[#This Row],[currency]]="€"),"EUR",IF(OR(Table1[[#This Row],[currency]]="USD",Table1[[#This Row],[currency]]="$"),"USD","Unknown")) -> USD | S16: delivered | T16: =IFERROR(_xlfn.XLOOKUP(Table1[[#This Row],[order_status]],Table8[Original],Table8[Clean],,0,1),"Unknown") -> Delivered | U16: 1 | V16: =IF(ISNUMBER(Table1[[#This Row],[delivery_days]]),Table1[[#This Row],[delivery_days]],IFERROR(_xlfn.XLOOKUP(Table1[[#This Row],[delivery_days]],Table57[Original],Table57[Clean],,0,1),"Unknown")) -> 1 | W16: VIP
B17: =IF(ISBLANK(Table1[[#This Row],[order_id]]),"",IF(LEFT(Table1[[#This Row],[order_id]],3)="ORD",Table1[[#This Row],[order_id]],"ORD-" & Table1[[#This Row],[order_id]])) | D17: =IFERROR(DATEVALUE(Table1[[#This Row],[order_date]]),"") | E17: customer 15 | F17: =IF(ISBLANK(Table1[[#This Row],[customer_name]]),"Unknown Customer",PROPER(SUBSTITUTE(Table1[[#This Row],[customer_name]],"Cust.","Customer"))) -> Customer 15 | G17: U.S. | H17: =IFERROR(_xlfn.XLOOKUP(Table1[[#This Row],[region]],Mappings!$C$3:$C$8,Mappings!$D$3:$D$8,,0,1),"Unknown") -> USA | I17: online | J17: =IFERROR(_xlfn.XLOOKUP(Table1[[#This Row],[sales_channel]],Table4[Original],Table4[Clean],,0,1),"Unknown") -> Online | K17: TABLET | L17: =IFERROR(_xlfn.XLOOKUP(Table1[[#This Row],[product]],Table3[Original],Table3[Product_clean],,0,1),"Unknown") -> Tablet | N17: =IF(ISNUMBER(Table1[[#This Row],[quantity]]),Table1[[#This Row],[quantity]],IFERROR(VLOOKUP(Table1[[#This Row],[quantity]],Table5[#All],2,FALSE),"Unknown")) -> Unknown | O17: $1566.76 | P17: =IFERROR(VALUE(SUBSTITUTE(SUBSTITUTE(SUBSTITUTE(Table1[[#This Row],[revenue]],"EUR",""),"$",""),".",",")),"") -> 1566.76 | R17: =IF(OR(Table1[[#This Row],[currency]]="EUR",Table1[[#This Row],[currency]]="€"),"EUR",IF(OR(Table1[[#This Row],[currency]]="USD",Table1[[#This Row],[currency]]="$"),"USD","Unknown")) -> Unknown | S17: returned | T17: =IFERROR(_xlfn.XLOOKUP(Table1[[#This Row],[order_status]],Table8[Original],Table8[Clean],,0,1),"Unknown") -> Returned | U17: 2 | V17: =IF(ISNUMBER(Table1[[#This Row],[delivery_days]]),Table1[[#This Row],[delivery_days]],IFERROR(_xlfn.XLOOKUP(Table1[[#This Row],[delivery_days]],Table57[Original],Table57[Clean],,0,1),"Unknown")) -> 2
A18: 1016 | B18: =IF(ISBLANK(Table1[[#This Row],[order_id]]),"",IF(LEFT(Table1[[#This Row],[order_id]],3)="ORD",Table1[[#This Row],[order_id]],"ORD-" & Table1[[#This Row],[order_id]])) -> ORD-1016 | D18: =IFERROR(DATEVALUE(Table1[[#This Row],[order_date]]),"") | E18: Cust. 16 | F18: =IF(ISBLANK(Table1[[#This Row],[customer_name]]),"Unknown Customer",PROPER(SUBSTITUTE(Table1[[#This Row],[customer_name]],"Cust.","Customer"))) -> Customer 16 | G18: europe | H18: =IFERROR(_xlfn.XLOOKUP(Table1[[#This Row],[region]],Mappings!$C$3:$C$8,Mappings!$D$3:$D$8,,0,1),"Unknown") -> Europe | I18: MOBILE | J18: =IFERROR(_xlfn.XLOOKUP(Table1[[#This Row],[sales_channel]],Table4[Original],Table4[Clean],,0,1),"Unknown") -> Mobile | K18: phone | L18: =IFERROR(_xlfn.XLOOKUP(Table1[[#This Row],[product]],Table3[Original],Table3[Product_clean],,0,1),"Unknown") -> Phone | M18: 1 | N18: =IF(ISNUMBER(Table1[[#This Row],[quantity]]),Table1[[#This Row],[quantity]],IFERROR(VLOOKUP(Table1[[#This Row],[quantity]],Table5[#All],2,FALSE),"Unknown")) -> 1 | O18: 1250.83 | P18: =IFERROR(VALUE(SUBSTITUTE(SUBSTITUTE(SUBSTITUTE(Table1[[#This Row],[revenue]],"EUR",""),"$",""),".",",")),"") -> 1250.83 | Q18: EUR | R18: =IF(OR(Table1[[#This Row],[currency]]="EUR",Table1[[#This Row],[currency]]="€"),"EUR",IF(OR(Table1[[#This Row],[currency]]="USD",Table1[[#This Row],[currency]]="$"),"USD","Unknown")) -> EUR | S18: delivered | T18: =IFERROR(_xlfn.XLOOKUP(Table1[[#This Row],[order_status]],Table8[Original],Table8[Clean],,0,1),"Unknown") -> Delivered | U18: 5 | V18: =IF(ISNUMBER(Table1[[#This Row],[delivery_days]]),Table1[[#This Row],[delivery_days]],IFERROR(_xlfn.XLOOKUP(Table1[[#This Row],[delivery_days]],Table57[Original],Table57[Clean],,0,1),"Unknown")) -> 5 | W18: VIP
A19: 1017 | B19: =IF(ISBLANK(Table1[[#This Row],[order_id]]),"",IF(LEFT(Table1[[#This Row],[order_id]],3)="ORD",Table1[[#This Row],[order_id]],"ORD-" & Table1[[#This Row],[order_id]])) -> ORD-1017 | C19: 13/02/2025 | D19: =IFERROR(DATEVALUE(Table1[[#This Row],[order_date]]),"") -> 45701 | F19: =IF(ISBLANK(Table1[[#This Row],[customer_name]]),"Unknown Customer",PROPER(SUBSTITUTE(Table1[[#This Row],[customer_name]],"Cust.","Customer"))) -> Unknown Customer | G19: US | H19: =IFERROR(_xlfn.XLOOKUP(Table1[[#This Row],[region]],Mappings!$C$3:$C$8,Mappings!$D$3:$D$8,,0,1),"Unknown") -> USA | I19: MOBILE | J19: =IFERROR(_xlfn.XLOOKUP(Table1[[#This Row],[sales_channel]],Table4[Original],Table4[Clean],,0,1),"Unknown") -> Mobile | K19: Lapotp | L19: =IFERROR(_xlfn.XLOOKUP(Table1[[#This Row],[product]],Table3[Original],Table3[Product_clean],,0,1),"Unknown") -> Laptop | M19: 3 | N19: =IF(ISNUMBER(Table1[[#This Row],[quantity]]),Table1[[#This Row],[quantity]],IFERROR(VLOOKUP(Table1[[#This Row],[quantity]],Table5[#All],2,FALSE),"Unknown")) -> 3 | O19: 2591.93 EUR | P19: =IFERROR(VALUE(SUBSTITUTE(SUBSTITUTE(SUBSTITUTE(Table1[[#This Row],[revenue]],"EUR",""),"$",""),".",",")),"") -> 2591.93 | Q19: $ | R19: =IF(OR(Table1[[#This Row],[currency]]="EUR",Table1[[#This Row],[currency]]="€"),"EUR",IF(OR(Table1[[#This Row],[currency]]="USD",Table1[[#This Row],[currency]]="$"),"USD","Unknown")) -> USD | S19: Delivered | T19: =IFERROR(_xlfn.XLOOKUP(Table1[[#This Row],[order_status]],Table8[Original],Table8[Clean],,0,1),"Unknown") -> Delivered | U19: 1 | V19: =IF(ISNUMBER(Table1[[#This Row],[delivery_days]]),Table1[[#This Row],[delivery_days]],IFERROR(_xlfn.XLOOKUP(Table1[[#This Row],[delivery_days]],Table57[Original],Table57[Clean],,0,1),"Unknown")) -> 1
A20: 1018 | B20: =IF(ISBLANK(Table1[[#This Row],[order_id]]),"",IF(LEFT(Table1[[#This Row],[order_id]],3)="ORD",Table1[[#This Row],[order_id]],"ORD-" & Table1[[#This Row],[order_id]])) -> ORD-1018 | C20: 2025-02-17 | D20: =IFERROR(DATEVALUE(Table1[[#This Row],[order_date]]),"") -> 45705 | E20: Customer 18 | F20: =IF(ISBLANK(Table1[[#This Row],[customer_name]]),"Unknown Customer",PROPER(SUBSTITUTE(Table1[[#This Row],[customer_name]],"Cust.","Customer"))) -> Customer 18 | H20: =IFERROR(_xlfn.XLOOKUP(Table1[[#This Row],[region]],Mappings!$C$3:$C$8,Mappings!$D$3:$D$8,,0,1),"Unknown") -> Unknown | I20: online | J20: =IFERROR(_xlfn.XLOOKUP(Table1[[#This Row],[sales_channel]],Table4[Original],Table4[Clean],,0,1),"Unknown") -> Online | K20: Lapotp | L20: =IFERROR(_xlfn.XLOOKUP(Table1[[#This Row],[product]],Table3[Original],Table3[Product_clean],,0,1),"Unknown") -> Laptop | M20: two | N20: =IF(ISNUMBER(Table1[[#This Row],[quantity]]),Table1[[#This Row],[quantity]],IFERROR(VLOOKUP(Table1[[#This Row],[quantity]],Table5[#All],2,FALSE),"Unknown")) -> 2 | O20: 2590.98 | P20: =IFERROR(VALUE(SUBSTITUTE(SUBSTITUTE(SUBSTITUTE(Table1[[#This Row],[revenue]],"EUR",""),"$",""),".",",")),"") -> 2590.98 | Q20: $ | R20: =IF(OR(Table1[[#This Row],[currency]]="EUR",Table1[[#This Row],[currency]]="€"),"EUR",IF(OR(Table1[[#This Row],[currency]]="USD",Table1[[#This Row],[currency]]="$"),"USD","Unknown")) -> USD | S20: returned | T20: =IFERROR(_xlfn.XLOOKUP(Table1[[#This Row],[order_status]],Table8[Original],Table8[Clean],,0,1),"Unknown") -> Returned | U20: 2 | V20: =IF(ISNUMBER(Table1[[#This Row],[delivery_days]]),Table1[[#This Row],[delivery_days]],IFERROR(_xlfn.XLOOKUP(Table1[[#This Row],[delivery_days]],Table57[Original],Table57[Clean],,0,1),"Unknown")) -> 2
A21: ORD-1019 | B21: =IF(ISBLANK(Table1[[#This Row],[order_id]]),"",IF(LEFT(Table1[[#This Row],[order_id]],3)="ORD",Table1[[#This Row],[order_id]],"ORD-" & Table1[[#This Row],[order_id]])) -> ORD-1019 | C21: 01-31-2024 | D21: =IFERROR(DATEVALUE(Table1[[#This Row],[order_date]]),"") | F21: =IF(ISBLANK(Table1[[#This Row],[customer_name]]),"Unknown Customer",PROPER(SUBSTITUTE(Table1[[#This Row],[customer_name]],"Cust.","Customer"))) -> Unknown Customer | G21: Asia | H21: =IFERROR(_xlfn.XLOOKUP(Table1[[#This Row],[region]],Mappings!$C$3:$C$8,Mappings!$D$3:$D$8,,0,1),"Unknown") -> Asia | I21: MOBILE | J21: =IFERROR(_xlfn.XLOOKUP(Table1[[#This Row],[sales_channel]],Table4[Original],Table4[Clean],,0,1),"Unknown") -> Mobile | K21: TABLET | L21: =IFERROR(_xlfn.XLOOKUP(Table1[[#This Row],[product]],Table3[Original],Table3[Product_clean],,0,1),"Unknown") -> Tablet | N21: =IF(ISNUMBER(Table1[[#This Row],[quantity]]),Table1[[#This Row],[quantity]],IFERROR(VLOOKUP(Table1[[#This Row],[quantity]],Table5[#All],2,FALSE),"Unknown")) -> Unknown | O21: 535.68 | P21: =IFERROR(VALUE(SUBSTITUTE(SUBSTITUTE(SUBSTITUTE(Table1[[#This Row],[revenue]],"EUR",""),"$",""),".",",")),"") -> 535.68 | Q21: $ | R21: =IF(OR(Table1[[#This Row],[currency]]="EUR",Table1[[#This Row],[currency]]="€"),"EUR",IF(OR(Table1[[#This Row],[currency]]="USD",Table1[[#This Row],[currency]]="$"),"USD","Unknown")) -> USD | S21: Delivered | T21: =IFERROR(_xlfn.XLOOKUP(Table1[[#This Row],[order_status]],Table8[Original],Table8[Clean],,0,1),"Unknown") -> Delivered | U21: 2 | V21: =IF(ISNUMBER(Table1[[#This Row],[delivery_days]]),Table1[[#This Row],[delivery_days]],IFERROR(_xlfn.XLOOKUP(Table1[[#This Row],[delivery_days]],Table57[Original],Table57[Clean],,0,1),"Unknown")) -> 2 | W21: VIP
B22: =IF(ISBLANK(Table1[[#This Row],[order_id]]),"",IF(LEFT(Table1[[#This Row],[order_id]],3)="ORD",Table1[[#This Row],[order_id]],"ORD-" & Table1[[#This Row],[order_id]])) | C22: 04-21-2024 | D22: =IFERROR(DATEVALUE(Table1[[#This Row],[order_date]]),"") | E22: Customer 20 | F22: =IF(ISBLANK(Table1[[#This Row],[customer_name]]),"Unknown Customer",PROPER(SUBSTITUTE(Table1[[#This Row],[customer_name]],"Cust.","Customer"))) -> Customer 20 | G22: EU | H22: =IFERROR(_xlfn.XLOOKUP(Table1[[#This Row],[region]],Mappings!$C$3:$C$8,Mappings!$D$3:$D$8,,0,1),"Unknown") -> Europe | I22: Web | J22: =IFERROR(_xlfn.XLOOKUP(Table1[[#This Row],[sales_channel]],Table4[Original],Table4[Clean],,0,1),"Unknown") -> Online | K22: phone | L22: =IFERROR(_xlfn.XLOOKUP(Table1[[#This Row],[product]],Table3[Original],Table3[Product_clean],,0,1),"Unknown") -> Phone | N22: =IF(ISNUMBER(Table1[[#This Row],[quantity]]),Table1[[#This Row],[quantity]],IFERROR(VLOOKUP(Table1[[#This Row],[quantity]],Table5[#All],2,FALSE),"Unknown")) -> Unknown | O22: 2907.69 | P22: =IFERROR(VALUE(SUBSTITUTE(SUBSTITUTE(SUBSTITUTE(Table1[[#This Row],[revenue]],"EUR",""),"$",""),".",",")),"") -> 2907.69 | R22: =IF(OR(Table1[[#This Row],[currency]]="EUR",Table1[[#This Row],[currency]]="€"),"EUR",IF(OR(Table1[[#This Row],[currency]]="USD",Table1[[#This Row],[currency]]="$"),"USD","Unknown")) -> Unknown | S22: Delivered | T22: =IFERROR(_xlfn.XLOOKUP(Table1[[#This Row],[order_status]],Table8[Original],Table8[Clean],,0,1),"Unknown") -> Delivered | U22: 1 | V22: =IF(ISNUMBER(Table1[[#This Row],[delivery_days]]),Table1[[#This Row],[delivery_days]],IFERROR(_xlfn.XLOOKUP(Table1[[#This Row],[delivery_days]],Table57[Original],Table57[Clean],,0,1),"Unknown")) -> 1
B23: =IF(ISBLANK(Table1[[#This Row],[order_id]]),"",IF(LEFT(Table1[[#This Row],[order_id]],3)="ORD",Table1[[#This Row],[order_id]],"ORD-" & Table1[[#This Row],[order_id]])) | C23: 05/04/2024 | D23: =IFERROR(DATEVALUE(Table1[[#This Row],[order_date]]),"") -> 45387 | F23: =IF(ISBLANK(Table1[[#This Row],[customer_name]]),"Unknown Customer",PROPER(SUBSTITUTE(Table1[[#This Row],[customer_name]],"Cust.","Customer"))) -> Unknown Customer | G23: EU | H23: =IFERROR(_xlfn.XLOOKUP(Table1[[#This Row],[region]],Mappings!$C$3:$C$8,Mappings!$D$3:$D$8,,0,1),"Unknown") -> Europe | I23: Web | J23: =IFERROR(_xlfn.XLOOKUP(Table1[[#This Row],[sales_channel]],Table4[Original],Table4[Clean],,0,1),"Unknown") -> Online | K23: Lapotp | L23: =IFERROR(_xlfn.XLOOKUP(Table1[[#This Row],[product]],Table3[Original],Table3[Product_clean],,0,1),"Unknown") -> Laptop | N23: =IF(ISNUMBER(Table1[[#This Row],[quantity]]),Table1[[#This Row],[quantity]],IFERROR(VLOOKUP(Table1[[#This Row],[quantity]],Table5[#All],2,FALSE),"Unknown")) -> Unknown | O23: 252.14 | P23: =IFERROR(VALUE(SUBSTITUTE(SUBSTITUTE(SUBSTITUTE(Table1[[#This Row],[revenue]],"EUR",""),"$",""),".",",")),"") -> 252.14 | R23: =IF(OR(Table1[[#This Row],[currency]]="EUR",Table1[[#This Row],[currency]]="€"),"EUR",IF(OR(Table1[[#This Row],[currency]]="USD",Table1[[#This Row],[currency]]="$"),"USD","Unknown")) -> Unknown | S23: delivered | T23: =IFERROR(_xlfn.XLOOKUP(Table1[[#This Row],[order_status]],Table8[Original],Table8[Clean],,0,1),"Unknown") -> Delivered | U23: five | V23: =IF(ISNUMBER(Table1[[#This Row],[delivery_days]]),Table1[[#This Row],[delivery_days]],IFERROR(_xlfn.XLOOKUP(Table1[[#This Row],[delivery_days]],Table57[Original],Table57[Clean],,0,1),"Unknown")) -> 5
A24: ORD-1022 | B24: =IF(ISBLANK(Table1[[#This Row],[order_id]]),"",IF(LEFT(Table1[[#This Row],[order_id]],3)="ORD",Table1[[#This Row],[order_id]],"ORD-" & Table1[[#This Row],[order_id]])) -> ORD-1022 | C24: 02/08/2024 | D24: =IFERROR(DATEVALUE(Table1[[#This Row],[order_date]]),"") -> 45506 | E24: Cust. 22 | F24: =IF(ISBLANK(Table1[[#This Row],[customer_name]]),"Unknown Customer",PROPER(SUBSTITUTE(Table1[[#This Row],[customer_name]],"Cust.","Customer"))) -> Customer 22 | G24: US | H24: =IFERROR(_xlfn.XLOOKUP(Table1[[#This Row],[region]],Mappings!$C$3:$C$8,Mappings!$D$3:$D$8,,0,1),"Unknown") -> USA | I24: Mobile | J24: =IFERROR(_xlfn.XLOOKUP(Table1[[#This Row],[sales_channel]],Table4[Original],Table4[Clean],,0,1),"Unknown") -> Mobile | K24: phone | L24: =IFERROR(_xlfn.XLOOKUP(Table1[[#This Row],[product]],Table3[Original],Table3[Product_clean],,0,1),"Unknown") -> Phone | M24: 2 | N24: =IF(ISNUMBER(Table1[[#This Row],[quantity]]),Table1[[#This Row],[quantity]],IFERROR(VLOOKUP(Table1[[#This Row],[quantity]],Table5[#All],2,FALSE),"Unknown")) -> 2 | O24: $1989.25 | P24: =IFERROR(VALUE(SUBSTITUTE(SUBSTITUTE(SUBSTITUTE(Table1[[#This Row],[revenue]],"EUR",""),"$",""),".",",")),"") -> 1989.25 | Q24: € | R24: =IF(OR(Table1[[#This Row],[currency]]="EUR",Table1[[#This Row],[currency]]="€"),"EUR",IF(OR(Table1[[#This Row],[currency]]="USD",Table1[[#This Row],[currency]]="$"),"USD","Unknown")) -> EUR | S24: returned | T24: =IFERROR(_xlfn.XLOOKUP(Table1[[#This Row],[order_status]],Table8[Original],Table8[Clean],,0,1),"Unknown") -> Returned | U24: 3 | V24: =IF(ISNUMBER(Table1[[#This Row],[delivery_days]]),Table1[[#This Row],[delivery_days]],IFERROR(_xlfn.XLOOKUP(Table1[[#This Row],[delivery_days]],Table57[Original],Table57[Clean],,0,1),"Unknown")) -> 3
A25: 1023 | B25: =IF(ISBLANK(Table1[[#This Row],[order_id]]),"",IF(LEFT(Table1[[#This Row],[order_id]],3)="ORD",Table1[[#This Row],[order_id]],"ORD-" & Table1[[#This Row],[order_id]])) -> ORD-1023 | C25: 05/01/2024 | D25: =IFERROR(DATEVALUE(Table1[[#This Row],[order_date]]),"") -> 45296 | E25: Cust. 23 | F25: =IF(ISBLANK(Table1[[#This Row],[customer_name]]),"Unknown Customer",PROPER(SUBSTITUTE(Table1[[#This Row],[customer_name]],"Cust.","Customer"))) -> Customer 23 | G25: US | H25: =IFERROR(_xlfn.XLOOKUP(Table1[[#This Row],[region]],Mappings!$C$3:$C$8,Mappings!$D$3:$D$8,,0,1),"Unknown") -> USA | I25: Mobile | J25: =IFERROR(_xlfn.XLOOKUP(Table1[[#This Row],[sales_channel]],Table4[Original],Table4[Clean],,0,1),"Unknown") -> Mobile | K25: Laptop | L25: =IFERROR(_xlfn.XLOOKUP(Table1[[#This Row],[product]],Table3[Original],Table3[Product_clean],,0,1),"Unknown") -> Laptop | M25: 2 | N25: =IF(ISNUMBER(Table1[[#This Row],[quantity]]),Table1[[#This Row],[quantity]],IFERROR(VLOOKUP(Table1[[#This Row],[quantity]],Table5[#All],2,FALSE),"Unknown")) -> 2 | O25: 1401.94 | P25: =IFERROR(VALUE(SUBSTITUTE(SUBSTITUTE(SUBSTITUTE(Table1[[#This Row],[revenue]],"EUR",""),"$",""),".",",")),"") -> 1401.94 | Q25: € | R25: =IF(OR(Table1[[#This Row],[currency]]="EUR",Table1[[#This Row],[currency]]="€"),"EUR",IF(OR(Table1[[#This Row],[currency]]="USD",Table1[[#This Row],[currency]]="$"),"USD","Unknown")) -> EUR | S25: RETURNED | T25: =IFERROR(_xlfn.XLOOKUP(Table1[[#This Row],[order_status]],Table8[Original],Table8[Clean],,0,1),"Unknown") -> Returned | U25: 2 | V25: =IF(ISNUMBER(Table1[[#This Row],[delivery_days]]),Table1[[#This Row],[delivery_days]],IFERROR(_xlfn.XLOOKUP(Table1[[#This Row],[delivery_days]],Table57[Original],Table57[Clean],,0,1),"Unknown")) -> 2
B26: =IF(ISBLANK(Table1[[#This Row],[order_id]]),"",IF(LEFT(Table1[[#This Row],[order_id]],3)="ORD",Table1[[#This Row],[order_id]],"ORD-" & Table1[[#This Row],[order_id]])) | C26: 10-05-2024 | D26: =IFERROR(DATEVALUE(Table1[[#This Row],[order_date]]),"") -> 45422 | E26: Customer 24 | F26: =IF(ISBLANK(Table1[[#This Row],[customer_name]]),"Unknown Customer",PROPER(SUBSTITUTE(Table1[[#This Row],[customer_name]],"Cust.","Customer"))) -> Customer 24 | G26: US | H26: =IFERROR(_xlfn.XLOOKUP(Table1[[#This Row],[region]],Mappings!$C$3:$C$8,Mappings!$D$3:$D$8,,0,1),"Unknown") -> USA | I26: Mobile | J26: =IFERROR(_xlfn.XLOOKUP(Table1[[#This Row],[sales_channel]],Table4[Original],Table4[Clean],,0,1),"Unknown") -> Mobile | K26: Laptop | L26: =IFERROR(_xlfn.XLOOKUP(Table1[[#This Row],[product]],Table3[Original],Table3[Product_clean],,0,1),"Unknown") -> Laptop | M26: 1 | N26: =IF(ISNUMBER(Table1[[#This Row],[quantity]]),Table1[[#This Row],[quantity]],IFERROR(VLOOKUP(Table1[[#This Row],[quantity]],Table5[#All],2,FALSE),"Unknown")) -> 1 | O26: 2125.44 | P26: =IFERROR(VALUE(SUBSTITUTE(SUBSTITUTE(SUBSTITUTE(Table1[[#This Row],[revenue]],"EUR",""),"$",""),".",",")),"") -> 2125.44 | R26: =IF(OR(Table1[[#This Row],[currency]]="EUR",Table1[[#This Row],[currency]]="€"),"EUR",IF(OR(Table1[[#This Row],[currency]]="USD",Table1[[#This Row],[currency]]="$"),"USD","Unknown")) -> Unknown | S26: Delivered | T26: =IFERROR(_xlfn.XLOOKUP(Table1[[#This Row],[order_status]],Table8[Original],Table8[Clean],,0,1),"Unknown") -> Delivered | U26: 3 | V26: =IF(ISNUMBER(Table1[[#This Row],[delivery_days]]),Table1[[#This Row],[delivery_days]],IFERROR(_xlfn.XLOOKUP(Table1[[#This Row],[delivery_days]],Table57[Original],Table57[Clean],,0,1),"Unknown")) -> 3 | W26: VIP
A27: 1025 | B27: =IF(ISBLANK(Table1[[#This Row],[order_id]]),"",IF(LEFT(Table1[[#This Row],[order_id]],3)="ORD",Table1[[#This Row],[order_id]],"ORD-" & Table1[[#This Row],[order_id]])) -> ORD-1025 | C27: 11-05-2024 | D27: =IFERROR(DATEVALUE(Table1[[#This Row],[order_date]]),"") -> 45423 | F27: =IF(ISBLANK(Table1[[#This Row],[customer_name]]),"Unknown Customer",PROPER(SUBSTITUTE(Table1[[#This Row],[customer_name]],"Cust.","Customer"))) -> Unknown Customer | G27: Asia | H27: =IFERROR(_xlfn.XLOOKUP(Table1[[#This Row],[region]],Mappings!$C$3:$C$8,Mappings!$D$3:$D$8,,0,1),"Unknown") -> Asia | I27: Online | J27: =IFERROR(_xlfn.XLOOKUP(Table1[[#This Row],[sales_channel]],Table4[Original],Table4[Clean],,0,1),"Unknown") -> Online | K27: Laptop | L27: =IFERROR(_xlfn.XLOOKUP(Table1[[#This Row],[product]],Table3[Original],Table3[Product_clean],,0,1),"Unknown") -> Laptop | M27: two | N27: =IF(ISNUMBER(Table1[[#This Row],[quantity]]),Table1[[#This Row],[quantity]],IFERROR(VLOOKUP(Table1[[#This Row],[quantity]],Table5[#All],2,FALSE),"Unknown")) -> 2 | O27: $671.36 | P27: =IFERROR(VALUE(SUBSTITUTE(SUBSTITUTE(SUBSTITUTE(Table1[[#This Row],[revenue]],"EUR",""),"$",""),".",",")),"") -> 671.36 | Q27: € | R27: =IF(OR(Table1[[#This Row],[currency]]="EUR",Table1[[#This Row],[currency]]="€"),"EUR",IF(OR(Table1[[#This Row],[currency]]="USD",Table1[[#This Row],[currency]]="$"),"USD","Unknown")) -> EUR | S27: delivered | T27: =IFERROR(_xlfn.XLOOKUP(Table1[[#This Row],[order_status]],Table8[Original],Table8[Clean],,0,1),"Unknown") -> Delivered | U27: 1 | V27: =IF(ISNUMBER(Table1[[#This Row],[delivery_days]]),Table1[[#This Row],[delivery_days]],IFERROR(_xlfn.XLOOKUP(Table1[[#This Row],[delivery_days]],Table57[Original],Table57[Clean],,0,1),"Unknown")) -> 1 | W27: VIP
A28: 1026 | B28: =IF(ISBLANK(Table1[[#This Row],[order_id]]),"",IF(LEFT(Table1[[#This Row],[order_id]],3)="ORD",Table1[[#This Row],[order_id]],"ORD-" & Table1[[#This Row],[order_id]])) -> ORD-1026 | D28: =IFERROR(DATEVALUE(Table1[[#This Row],[order_date]]),"") | F28: =IF(ISBLANK(Table1[[#This Row],[customer_name]]),"Unknown Customer",PROPER(SUBSTITUTE(Table1[[#This Row],[customer_name]],"Cust.","Customer"))) -> Unknown Customer | G28: U.S. | H28: =IFERROR(_xlfn.XLOOKUP(Table1[[#This Row],[region]],Mappings!$C$3:$C$8,Mappings!$D$3:$D$8,,0,1),"Unknown") -> USA | I28: Online | J28: =IFERROR(_xlfn.XLOOKUP(Table1[[#This Row],[sales_channel]],Table4[Original],Table4[Clean],,0,1),"Unknown") -> Online | K28: Laptop | L28: =IFERROR(_xlfn.XLOOKUP(Table1[[#This Row],[product]],Table3[Original],Table3[Product_clean],,0,1),"Unknown") -> Laptop | M28: 1 | N28: =IF(ISNUMBER(Table1[[#This Row],[quantity]]),Table1[[#This Row],[quantity]],IFERROR(VLOOKUP(Table1[[#This Row],[quantity]],Table5[#All],2,FALSE),"Unknown")) -> 1 | O28: $435.92 | P28: =IFERROR(VALUE(SUBSTITUTE(SUBSTITUTE(SUBSTITUTE(Table1[[#This Row],[revenue]],"EUR",""),"$",""),".",",")),"") -> 435.92 | Q28: USD | R28: =IF(OR(Table1[[#This Row],[currency]]="EUR",Table1[[#This Row],[currency]]="€"),"EUR",IF(OR(Table1[[#This Row],[currency]]="USD",Table1[[#This Row],[currency]]="$"),"USD","Unknown")) -> USD | S28: pending | T28: =IFERROR(_xlfn.XLOOKUP(Table1[[#This Row],[order_status]],Table8[Original],Table8[Clean],,0,1),"Unknown") -> Pending | U28: 1 | V28: =IF(ISNUMBER(Table1[[#This Row],[delivery_days]]),Table1[[#This Row],[delivery_days]],IFERROR(_xlfn.XLOOKUP(Table1[[#This Row],[delivery_days]],Table57[Original],Table57[Clean],,0,1),"Unknown")) -> 1 | W28: VIP
A29: 1027 | B29: =IF(ISBLANK(Table1[[#This Row],[order_id]]),"",IF(LEFT(Table1[[#This Row],[order_id]],3)="ORD",Table1[[#This Row],[order_id]],"ORD-" & Table1[[#This Row],[order_id]])) -> ORD-1027 | C29: 2024-10-25 | D29: =IFERROR(DATEVALUE(Table1[[#This Row],[order_date]]),"") -> 45590 | E29: Cust. 27 | F29: =IF(ISBLANK(Table1[[#This Row],[customer_name]]),"Unknown Customer",PROPER(SUBSTITUTE(Table1[[#This Row],[customer_name]],"Cust.","Customer"))) -> Customer 27 | G29: Asia | H29: =IFERROR(_xlfn.XLOOKUP(Table1[[#This Row],[region]],Mappings!$C$3:$C$8,Mappings!$D$3:$D$8,,0,1),"Unknown") -> Asia | I29: Online | J29: =IFERROR(_xlfn.XLOOKUP(Table1[[#This Row],[sales_channel]],Table4[Original],Table4[Clean],,0,1),"Unknown") -> Online | K29: Phone | L29: =IFERROR(_xlfn.XLOOKUP(Table1[[#This Row],[product]],Table3[Original],Table3[Product_clean],,0,1),"Unknown") -> Phone | M29: 2 | N29: =IF(ISNUMBER(Table1[[#This Row],[quantity]]),Table1[[#This Row],[quantity]],IFERROR(VLOOKUP(Table1[[#This Row],[quantity]],Table5[#All],2,FALSE),"Unknown")) -> 2 | P29: =IFERROR(VALUE(SUBSTITUTE(SUBSTITUTE(SUBSTITUTE(Table1[[#This Row],[revenue]],"EUR",""),"$",""),".",",")),"") | Q29: USD | R29: =IF(OR(Table1[[#This Row],[currency]]="EUR",Table1[[#This Row],[currency]]="€"),"EUR",IF(OR(Table1[[#This Row],[currency]]="USD",Table1[[#This Row],[currency]]="$"),"USD","Unknown")) -> USD | T29: =IFERROR(_xlfn.XLOOKUP(Table1[[#This Row],[order_status]],Table8[Original],Table8[Clean],,0,1),"Unknown") -> Unknown | U29: 1 | V29: =IF(ISNUMBER(Table1[[#This Row],[delivery_days]]),Table1[[#This Row],[delivery_days]],IFERROR(_xlfn.XLOOKUP(Table1[[#This Row],[delivery_days]],Table57[Original],Table57[Clean],,0,1),"Unknown")) -> 1 | W29: VIP
B30: =IF(ISBLANK(Table1[[#This Row],[order_id]]),"",IF(LEFT(Table1[[#This Row],[order_id]],3)="ORD",Table1[[#This Row],[order_id]],"ORD-" & Table1[[#This Row],[order_id]])) | C30: 03/02/2025 | D30: =IFERROR(DATEVALUE(Table1[[#This Row],[order_date]]),"") -> 45691 | E30: customer 28 | F30: =IF(ISBLANK(Table1[[#This Row],[customer_name]]),"Unknown Customer",PROPER(SUBSTITUTE(Table1[[#This Row],[customer_name]],"Cust.","Customer"))) -> Customer 28 | H30: =IFERROR(_xlfn.XLOOKUP(Table1[[#This Row],[region]],Mappings!$C$3:$C$8,Mappings!$D$3:$D$8,,0,1),"Unknown") -> Unknown | I30: online | J30: =IFERROR(_xlfn.XLOOKUP(Table1[[#This Row],[sales_channel]],Table4[Original],Table4[Clean],,0,1),"Unknown") -> Online | L30: =IFERROR(_xlfn.XLOOKUP(Table1[[#This Row],[product]],Table3[Original],Table3[Product_clean],,0,1),"Unknown") -> Unknown | M30: 2 | N30: =IF(ISNUMBER(Table1[[#This Row],[quantity]]),Table1[[#This Row],[quantity]],IFERROR(VLOOKUP(Table1[[#This Row],[quantity]],Table5[#All],2,FALSE),"Unknown")) -> 2 | P30: =IFERROR(VALUE(SUBSTITUTE(SUBSTITUTE(SUBSTITUTE(Table1[[#This Row],[revenue]],"EUR",""),"$",""),".",",")),"") | Q30: $ | R30: =IF(OR(Table1[[#This Row],[currency]]="EUR",Table1[[#This Row],[currency]]="€"),"EUR",IF(OR(Table1[[#This Row],[currency]]="USD",Table1[[#This Row],[currency]]="$"),"USD","Unknown")) -> USD | S30: delivered | T30: =IFERROR(_xlfn.XLOOKUP(Table1[[#This Row],[order_status]],Table8[Original],Table8[Clean],,0,1),"Unknown") -> Delivered | U30: 2 | V30: =IF(ISNUMBER(Table1[[#This Row],[delivery_days]]),Table1[[#This Row],[delivery_days]],IFERROR(_xlfn.XLOOKUP(Table1[[#This Row],[delivery_days]],Table57[Original],Table57[Clean],,0,1),"Unknown")) -> 2 | W30: VIP
A31: ORD-1029 | B31: =IF(ISBLANK(Table1[[#This Row],[order_id]]),"",IF(LEFT(Table1[[#This Row],[order_id]],3)="ORD",Table1[[#This Row],[order_id]],"ORD-" & Table1[[#This Row],[order_id]])) -> ORD-1029 | C31: 04/02/2025 | D31: =IFERROR(DATEVALUE(Table1[[#This Row],[order_date]]),"") -> 45692 | E31: Customer 29 | F31: =IF(ISBLANK(Table1[[#This Row],[customer_name]]),"Unknown Customer",PROPER(SUBSTITUTE(Table1[[#This Row],[customer_name]],"Cust.","Customer"))) -> Customer 29 | G31: europe | H31: =IFERROR(_xlfn.XLOOKUP(Table1[[#This Row],[region]],Mappings!$C$3:$C$8,Mappings!$D$3:$D$8,,0,1),"Unknown") -> Europe | I31: Online | J31: =IFERROR(_xlfn.XLOOKUP(Table1[[#This Row],[sales_channel]],Table4[Original],Table4[Clean],,0,1),"Unknown") -> Online | L31: =IFERROR(_xlfn.XLOOKUP(Table1[[#This Row],[product]],Table3[Original],Table3[Product_clean],,0,1),"Unknown") -> Unknown | M31: two | N31: =IF(ISNUMBER(Table1[[#This Row],[quantity]]),Table1[[#This Row],[quantity]],IFERROR(VLOOKUP(Table1[[#This Row],[quantity]],Table5[#All],2,FALSE),"Unknown")) -> 2 | O31: 2795.91 EUR | P31: =IFERROR(VALUE(SUBSTITUTE(SUBSTITUTE(SUBSTITUTE(Table1[[#This Row],[revenue]],"EUR",""),"$",""),".",",")),"") -> 2795.91 | Q31: USD | R31: =IF(OR(Table1[[#This Row],[currency]]="EUR",Table1[[#This Row],[currency]]="€"),"EUR",IF(OR(Table1[[#This Row],[currency]]="USD",Table1[[#This Row],[currency]]="$"),"USD","Unknown")) -> USD | S31: Delivered | T31: =IFERROR(_xlfn.XLOOKUP(Table1[[#This Row],[order_status]],Table8[Original],Table8[Clean],,0,1),"Unknown") -> Delivered | U31: 5 | V31: =IF(ISNUMBER(Table1[[#This Row],[delivery_days]]),Table1[[#This Row],[delivery_days]],IFERROR(_xlfn.XLOOKUP(Table1[[#This Row],[delivery_days]],Table57[Original],Table57[Clean],,0,1),"Unknown")) -> 5 | W31: VIP
A32: 1030 | B32: =IF(ISBLANK(Table1[[#This Row],[order_id]]),"",IF(LEFT(Table1[[#This Row],[order_id]],3)="ORD",Table1[[#This Row],[order_id]],"ORD-" & Table1[[#This Row],[order_id]])) -> ORD-1030 | C32: 2024-06-05 | D32: =IFERROR(DATEVALUE(Table1[[#This Row],[order_date]]),"") -> 45448 | E32: customer 30 | F32: =IF(ISBLANK(Table1[[#This Row],[customer_name]]),"Unknown Customer",PROPER(SUBSTITUTE(Table1[[#This Row],[customer_name]],"Cust.","Customer"))) -> Customer 30 | G32: europe | H32: =IFERROR(_xlfn.XLOOKUP(Table1[[#This Row],[region]],Mappings!$C$3:$C$8,Mappings!$D$3:$D$8,,0,1),"Unknown") -> Europe | I32: Mobile | J32: =IFERROR(_xlfn.XLOOKUP(Table1[[#This Row],[sales_channel]],Table4[Original],Table4[Clean],,0,1),"Unknown") -> Mobile | K32: Phone | L32: =IFERROR(_xlfn.XLOOKUP(Table1[[#This Row],[product]],Table3[Original],Table3[Product_clean],,0,1),"Unknown") -> Phone | M32: 1 | N32: =IF(ISNUMBER(Table1[[#This Row],[quantity]]),Table1[[#This Row],[quantity]],IFERROR(VLOOKUP(Table1[[#This Row],[quantity]],Table5[#All],2,FALSE),"Unknown")) -> 1 | O32: 2470.58 EUR | P32: =IFERROR(VALUE(SUBSTITUTE(SUBSTITUTE(SUBSTITUTE(Table1[[#This Row],[revenue]],"EUR",""),"$",""),".",",")),"") -> 2470.58 | Q32: € | R32: =IF(OR(Table1[[#This Row],[currency]]="EUR",Table1[[#This Row],[currency]]="€"),"EUR",IF(OR(Table1[[#This Row],[currency]]="USD",Table1[[#This Row],[currency]]="$"),"USD","Unknown")) -> EUR | S32: RETURNED | T32: =IFERROR(_xlfn.XLOOKUP(Table1[[#This Row],[order_status]],Table8[Original],Table8[Clean],,0,1),"Unknown") -> Returned | V32: =IF(ISNUMBER(Table1[[#This Row],[delivery_days]]),Table1[[#This Row],[delivery_days]],IFERROR(_xlfn.XLOOKUP(Table1[[#This Row],[delivery_days]],Table57[Original],Table57[Clean],,0,1),"Unknown")) -> Unknown
A33: 1031 | B33: =IF(ISBLANK(Table1[[#This Row],[order_id]]),"",IF(LEFT(Table1[[#This Row],[order_id]],3)="ORD",Table1[[#This Row],[order_id]],"ORD-" & Table1[[#This Row],[order_id]])) -> ORD-1031 | C33: 2024-12-13 | D33: =IFERROR(DATEVALUE(Table1[[#This Row],[order_date]]),"") -> 45639 | E33: Cust. 31 | F33: =IF(ISBLANK(Table1[[#This Row],[customer_name]]),"Unknown Customer",PROPER(SUBSTITUTE(Table1[[#This Row],[customer_name]],"Cust.","Customer"))) -> Customer 31 | G33: US | H33: =IFERROR(_xlfn.XLOOKUP(Table1[[#This Row],[region]],Mappings!$C$3:$C$8,Mappings!$D$3:$D$8,,0,1),"Unknown") -> USA | I33: Web | J33: =IFERROR(_xlfn.XLOOKUP(Table1[[#This Row],[sales_channel]],Table4[Original],Table4[Clean],,0,1),"Unknown") -> Online | K33: Phone | L33: =IFERROR(_xlfn.XLOOKUP(Table1[[#This Row],[product]],Table3[Original],Table3[Product_clean],,0,1),"Unknown") -> Phone | M33: 1 | N33: =IF(ISNUMBER(Table1[[#This Row],[quantity]]),Table1[[#This Row],[quantity]],IFERROR(VLOOKUP(Table1[[#This Row],[quantity]],Table5[#All],2,FALSE),"Unknown")) -> 1 | O33: $2944.39 | P33: =IFERROR(VALUE(SUBSTITUTE(SUBSTITUTE(SUBSTITUTE(Table1[[#This Row],[revenue]],"EUR",""),"$",""),".",",")),"") -> 2944.39 | Q33: EUR | R33: =IF(OR(Table1[[#This Row],[currency]]="EUR",Table1[[#This Row],[currency]]="€"),"EUR",IF(OR(Table1[[#This Row],[currency]]="USD",Table1[[#This Row],[currency]]="$"),"USD","Unknown")) -> EUR | S33: pending | T33: =IFERROR(_xlfn.XLOOKUP(Table1[[#This Row],[order_status]],Table8[Original],Table8[Clean],,0,1),"Unknown") -> Pending | U33: 5 | V33: =IF(ISNUMBER(Table1[[#This Row],[delivery_days]]),Table1[[#This Row],[delivery_days]],IFERROR(_xlfn.XLOOKUP(Table1[[#This Row],[delivery_days]],Table57[Original],Table57[Clean],,0,1),"Unknown")) -> 5 | W33: VIP
B34: =IF(ISBLANK(Table1[[#This Row],[order_id]]),"",IF(LEFT(Table1[[#This Row],[order_id]],3)="ORD",Table1[[#This Row],[order_id]],"ORD-" & Table1[[#This Row],[order_id]])) | C34: 2025-01-08 | D34: =IFERROR(DATEVALUE(Table1[[#This Row],[order_date]]),"") -> 45665 | F34: =IF(ISBLANK(Table1[[#This Row],[customer_name]]),"Unknown Customer",PROPER(SUBSTITUTE(Table1[[#This Row],[customer_name]],"Cust.","Customer"))) -> Unknown Customer | G34: U.S. | H34: =IFERROR(_xlfn.XLOOKUP(Table1[[#This Row],[region]],Mappings!$C$3:$C$8,Mappings!$D$3:$D$8,,0,1),"Unknown") -> USA | I34: online | J34: =IFERROR(_xlfn.XLOOKUP(Table1[[#This Row],[sales_channel]],Table4[Original],Table4[Clean],,0,1),"Unknown") -> Online | K34: Phone | L34: =IFERROR(_xlfn.XLOOKUP(Table1[[#This Row],[product]],Table3[Original],Table3[Product_clean],,0,1),"Unknown") -> Phone | M34: 1 | N34: =IF(ISNUMBER(Table1[[#This Row],[quantity]]),Table1[[#This Row],[quantity]],IFERROR(VLOOKUP(Table1[[#This Row],[quantity]],Table5[#All],2,FALSE),"Unknown")) -> 1 | P34: =IFERROR(VALUE(SUBSTITUTE(SUBSTITUTE(SUBSTITUTE(Table1[[#This Row],[revenue]],"EUR",""),"$",""),".",",")),"") | Q34: $ | R34: =IF(OR(Table1[[#This Row],[currency]]="EUR",Table1[[#This Row],[currency]]="€"),"EUR",IF(OR(Table1[[#This Row],[currency]]="USD",Table1[[#This Row],[currency]]="$"),"USD","Unknown")) -> USD | S34: delivered | T34: =IFERROR(_xlfn.XLOOKUP(Table1[[#This Row],[order_status]],Table8[Original],Table8[Clean],,0,1),"Unknown") -> Delivered | U34: five | V34: =IF(ISNUMBER(Table1[[#This Row],[delivery_days]]),Table1[[#This Row],[delivery_days]],IFERROR(_xlfn.XLOOKUP(Table1[[#This Row],[delivery_days]],Table57[Original],Table57[Clean],,0,1),"Unknown")) -> 5 | W34: late delivery
